[2018-06-04 19:13:43 +0800] [6961] [DEBUG] Current configuration:
  config: gunicorn.conf.py
  bind: ['127.0.0.1:9000']
  backlog: 2048
  workers: 1
  worker_class: sync
  threads: 1
  worker_connections: 1000
  max_requests: 0
  max_requests_jitter: 0
  timeout: 30
  graceful_timeout: 30
  keepalive: 2
  limit_request_line: 4094
  limit_request_fields: 100
  limit_request_field_size: 8190
  reload: False
  reload_engine: auto
  reload_extra_files: []
  spew: False
  check_config: False
  preload_app: False
  sendfile: None
  reuse_port: False
  chdir: /Users/teojpl/Documents/entry_task/eventsite
  daemon: False
  raw_env: []
  pidfile: None
  worker_tmp_dir: None
  user: 1285809910
  group: 1032302077
  umask: 0
  initgroups: False
  tmp_upload_dir: None
  secure_scheme_headers: {'X-FORWARDED-PROTOCOL': 'ssl', 'X-FORWARDED-PROTO': 'https', 'X-FORWARDED-SSL': 'on'}
  forwarded_allow_ips: ['127.0.0.1']
  accesslog: /Users/teojpl/Documents/entry_task/eventsite/logs/gunicorn-access.log
  disable_redirect_access_to_syslog: False
  access_log_format: %(h)s %(l)s %(u)s %(t)s "%(r)s" %(s)s %(b)s "%(f)s" "%(a)s"
  errorlog: /Users/teojpl/Documents/entry_task/eventsite/logs/gunicorn-error.log
  loglevel: debug
  capture_output: False
  logger_class: gunicorn.glogging.Logger
  logconfig: None
  logconfig_dict: {}
  syslog_addr: unix:///var/run/syslog
  syslog: False
  syslog_prefix: None
  syslog_facility: user
  enable_stdio_inheritance: False
  statsd_host: None
  statsd_prefix: 
  proc_name: None
  default_proc_name: eventapp.wsgi
  pythonpath: None
  paste: None
  on_starting: <function OnStarting.on_starting at 0x10e4828c8>
  on_reload: <function OnReload.on_reload at 0x10e4829d8>
  when_ready: <function WhenReady.when_ready at 0x10e482ae8>
  pre_fork: <function Prefork.pre_fork at 0x10e482bf8>
  post_fork: <function Postfork.post_fork at 0x10e482d08>
  post_worker_init: <function PostWorkerInit.post_worker_init at 0x10e482e18>
  worker_int: <function WorkerInt.worker_int at 0x10e482f28>
  worker_abort: <function WorkerAbort.worker_abort at 0x10e49f0d0>
  pre_exec: <function PreExec.pre_exec at 0x10e49f1e0>
  pre_request: <function PreRequest.pre_request at 0x10e49f2f0>
  post_request: <function PostRequest.post_request at 0x10e49f378>
  child_exit: <function ChildExit.child_exit at 0x10e49f488>
  worker_exit: <function WorkerExit.worker_exit at 0x10e49f598>
  nworkers_changed: <function NumWorkersChanged.nworkers_changed at 0x10e49f6a8>
  on_exit: <function OnExit.on_exit at 0x10e49f7b8>
  proxy_protocol: False
  proxy_allow_ips: ['127.0.0.1']
  keyfile: None
  certfile: None
  ssl_version: 2
  cert_reqs: 0
  ca_certs: None
  suppress_ragged_eofs: True
  do_handshake_on_connect: False
  ciphers: TLSv1
  raw_paste_global_conf: []
[2018-06-04 19:13:43 +0800] [6961] [INFO] Starting gunicorn 19.8.1
[2018-06-04 19:13:43 +0800] [6961] [DEBUG] Arbiter booted
[2018-06-04 19:13:43 +0800] [6961] [INFO] Listening at: http://127.0.0.1:9000 (6961)
[2018-06-04 19:13:43 +0800] [6961] [INFO] Using worker: sync
[2018-06-04 19:13:43 +0800] [6964] [INFO] Booting worker with pid: 6964
[2018-06-04 19:13:43 +0800] [6964] [ERROR] Exception in worker process
Traceback (most recent call last):
  File "/usr/local/lib/python3.6/site-packages/gunicorn/arbiter.py", line 583, in spawn_worker
    worker.init_process()
  File "/usr/local/lib/python3.6/site-packages/gunicorn/workers/base.py", line 129, in init_process
    self.load_wsgi()
  File "/usr/local/lib/python3.6/site-packages/gunicorn/workers/base.py", line 138, in load_wsgi
    self.wsgi = self.app.wsgi()
  File "/usr/local/lib/python3.6/site-packages/gunicorn/app/base.py", line 67, in wsgi
    self.callable = self.load()
  File "/usr/local/lib/python3.6/site-packages/gunicorn/app/wsgiapp.py", line 52, in load
    return self.load_wsgiapp()
  File "/usr/local/lib/python3.6/site-packages/gunicorn/app/wsgiapp.py", line 41, in load_wsgiapp
    return util.import_app(self.app_uri)
  File "/usr/local/lib/python3.6/site-packages/gunicorn/util.py", line 350, in import_app
    __import__(module)
ModuleNotFoundError: No module named 'eventapp.wsgi'
[2018-06-04 19:13:43 +0800] [6964] [INFO] Worker exiting (pid: 6964)
[2018-06-04 19:13:43 +0800] [6961] [DEBUG] 1 workers
[2018-06-04 19:13:43 +0800] [6961] [INFO] Shutting down: Master
[2018-06-04 19:13:43 +0800] [6961] [INFO] Reason: Worker failed to boot.
